{
 "cells": [
  {
   "cell_type": "code",
   "execution_count": 2,
   "metadata": {},
   "outputs": [
    {
     "name": "stdout",
     "output_type": "stream",
     "text": [
      "Collecting pandas\n",
      "  Downloading pandas-2.2.0-cp39-cp39-manylinux_2_17_x86_64.manylinux2014_x86_64.whl (13.0 MB)\n",
      "\u001b[K     |████████████████████████████████| 13.0 MB 114 kB/s eta 0:00:01    |███▉                            | 1.6 MB 439 kB/s eta 0:00:27     |████████                        | 3.2 MB 829 kB/s eta 0:00:12     |█████████▎                      | 3.8 MB 659 kB/s eta 0:00:15     |█████████▌                      | 3.9 MB 659 kB/s eta 0:00:14     |███████████████████████████████▏| 12.7 MB 1.1 MB/s eta 0:00:01\n",
      "\u001b[?25hCollecting pytz>=2020.1\n",
      "  Using cached pytz-2024.1-py2.py3-none-any.whl (505 kB)\n",
      "Requirement already satisfied: numpy<2,>=1.22.4; python_version < \"3.11\" in /home/musbah/.local/lib/python3.9/site-packages (from pandas) (1.26.4)\n",
      "Requirement already satisfied: python-dateutil>=2.8.2 in /home/musbah/.local/lib/python3.9/site-packages (from pandas) (2.8.2)\n",
      "Collecting tzdata>=2022.7\n",
      "  Using cached tzdata-2023.4-py2.py3-none-any.whl (346 kB)\n",
      "Requirement already satisfied: six>=1.5 in /usr/lib/python3/dist-packages (from python-dateutil>=2.8.2->pandas) (1.14.0)\n",
      "Installing collected packages: pytz, tzdata, pandas\n",
      "Successfully installed pandas-2.2.0 pytz-2024.1 tzdata-2023.4\n",
      "Note: you may need to restart the kernel to use updated packages.\n"
     ]
    }
   ],
   "source": [
    "%pip install pandas"
   ]
  },
  {
   "cell_type": "code",
   "execution_count": 1,
   "metadata": {},
   "outputs": [
    {
     "ename": "AttributeError",
     "evalue": "partially initialized module 'numpy' has no attribute 'array' (most likely due to a circular import)",
     "output_type": "error",
     "traceback": [
      "\u001b[0;31m---------------------------------------------------------------------------\u001b[0m",
      "\u001b[0;31mAttributeError\u001b[0m                            Traceback (most recent call last)",
      "Cell \u001b[0;32mIn[1], line 1\u001b[0m\n\u001b[0;32m----> 1\u001b[0m \u001b[38;5;28;01mimport\u001b[39;00m \u001b[38;5;21;01mpandas\u001b[39;00m \u001b[38;5;28;01mas\u001b[39;00m \u001b[38;5;21;01mpd\u001b[39;00m\n",
      "File \u001b[0;32m~/.local/lib/python3.9/site-packages/pandas/__init__.py:14\u001b[0m\n\u001b[1;32m     12\u001b[0m \u001b[38;5;28;01mfor\u001b[39;00m _dependency \u001b[38;5;129;01min\u001b[39;00m _hard_dependencies:\n\u001b[1;32m     13\u001b[0m     \u001b[38;5;28;01mtry\u001b[39;00m:\n\u001b[0;32m---> 14\u001b[0m         \u001b[38;5;28;43m__import__\u001b[39;49m\u001b[43m(\u001b[49m\u001b[43m_dependency\u001b[49m\u001b[43m)\u001b[49m\n\u001b[1;32m     15\u001b[0m     \u001b[38;5;28;01mexcept\u001b[39;00m \u001b[38;5;167;01mImportError\u001b[39;00m \u001b[38;5;28;01mas\u001b[39;00m _e:  \u001b[38;5;66;03m# pragma: no cover\u001b[39;00m\n\u001b[1;32m     16\u001b[0m         _missing_dependencies\u001b[38;5;241m.\u001b[39mappend(\u001b[38;5;124mf\u001b[39m\u001b[38;5;124m\"\u001b[39m\u001b[38;5;132;01m{\u001b[39;00m_dependency\u001b[38;5;132;01m}\u001b[39;00m\u001b[38;5;124m: \u001b[39m\u001b[38;5;132;01m{\u001b[39;00m_e\u001b[38;5;132;01m}\u001b[39;00m\u001b[38;5;124m\"\u001b[39m)\n",
      "File \u001b[0;32m~/projects/Data-Science-Assingment/numpy.py:3\u001b[0m\n\u001b[1;32m      1\u001b[0m \u001b[38;5;28;01mimport\u001b[39;00m \u001b[38;5;21;01mnumpy\u001b[39;00m \u001b[38;5;28;01mas\u001b[39;00m \u001b[38;5;21;01mnp\u001b[39;00m\n\u001b[0;32m----> 3\u001b[0m arr \u001b[38;5;241m=\u001b[39m \u001b[43mnp\u001b[49m\u001b[38;5;241;43m.\u001b[39;49m\u001b[43marray\u001b[49m([\u001b[38;5;241m1\u001b[39m, \u001b[38;5;241m2\u001b[39m, \u001b[38;5;241m3\u001b[39m, \u001b[38;5;241m4\u001b[39m, \u001b[38;5;241m5\u001b[39m])\n\u001b[1;32m      5\u001b[0m \u001b[38;5;28mprint\u001b[39m(arr)\n",
      "\u001b[0;31mAttributeError\u001b[0m: partially initialized module 'numpy' has no attribute 'array' (most likely due to a circular import)"
     ]
    }
   ],
   "source": [
    "import pandas as pd"
   ]
  },
  {
   "cell_type": "code",
   "execution_count": null,
   "metadata": {},
   "outputs": [],
   "source": []
  }
 ],
 "metadata": {
  "kernelspec": {
   "display_name": "Python 3",
   "language": "python",
   "name": "python3"
  },
  "language_info": {
   "codemirror_mode": {
    "name": "ipython",
    "version": 3
   },
   "file_extension": ".py",
   "mimetype": "text/x-python",
   "name": "python",
   "nbconvert_exporter": "python",
   "pygments_lexer": "ipython3",
   "version": "3.9.18"
  }
 },
 "nbformat": 4,
 "nbformat_minor": 2
}
